[2024-02-19T09:31:13.326+0000] {taskinstance.py:1957} INFO - Dependencies all met for dep_context=non-requeueable deps ti=<TaskInstance: final_project.Run_data_quality_checks manual__2024-02-19T09:25:05.177058+00:00 [queued]>
[2024-02-19T09:31:13.332+0000] {taskinstance.py:1957} INFO - Dependencies all met for dep_context=requeueable deps ti=<TaskInstance: final_project.Run_data_quality_checks manual__2024-02-19T09:25:05.177058+00:00 [queued]>
[2024-02-19T09:31:13.332+0000] {taskinstance.py:2171} INFO - Starting attempt 2 of 4
[2024-02-19T09:31:13.338+0000] {taskinstance.py:2192} INFO - Executing <Task(DataQualityOperator): Run_data_quality_checks> on 2024-02-19 09:25:05.177058+00:00
[2024-02-19T09:31:13.341+0000] {standard_task_runner.py:60} INFO - Started process 765 to run task
[2024-02-19T09:31:13.344+0000] {standard_task_runner.py:87} INFO - Running: ['***', 'tasks', 'run', 'final_project', 'Run_data_quality_checks', 'manual__2024-02-19T09:25:05.177058+00:00', '--job-id', '164', '--raw', '--subdir', 'DAGS_FOLDER/final_project.py', '--cfg-path', '/tmp/tmp2mstf0n4']
[2024-02-19T09:31:13.346+0000] {standard_task_runner.py:88} INFO - Job 164: Subtask Run_data_quality_checks
[2024-02-19T09:31:13.372+0000] {task_command.py:423} INFO - Running <TaskInstance: final_project.Run_data_quality_checks manual__2024-02-19T09:25:05.177058+00:00 [running]> on host b8bde2aaf906
[2024-02-19T09:31:13.407+0000] {taskinstance.py:2481} INFO - Exporting env vars: AIRFLOW_CTX_DAG_OWNER='udacity' AIRFLOW_CTX_DAG_ID='final_project' AIRFLOW_CTX_TASK_ID='Run_data_quality_checks' AIRFLOW_CTX_EXECUTION_DATE='2024-02-19T09:25:05.177058+00:00' AIRFLOW_CTX_TRY_NUMBER='2' AIRFLOW_CTX_DAG_RUN_ID='manual__2024-02-19T09:25:05.177058+00:00'
[2024-02-19T09:31:13.412+0000] {base.py:83} INFO - Using connection ID 'aws_credentials' for task execution.
[2024-02-19T09:31:13.413+0000] {connection_wrapper.py:378} INFO - AWS Connection (conn_id='aws_credentials', conn_type='aws') credentials retrieved from login and password.
[2024-02-19T09:31:13.423+0000] {base.py:83} INFO - Using connection ID 'redshift' for task execution.
[2024-02-19T09:31:20.235+0000] {sql.py:432} INFO - Running statement: SELECT COUNT(*) FROM dim.dim_users WHERE userid is null, parameters: None
[2024-02-19T09:31:25.455+0000] {sql.py:441} INFO - Rows affected: 1
[2024-02-19T09:31:25.993+0000] {data_quality.py:35} INFO - Data quality on query SELECT COUNT(*) FROM dim.dim_users WHERE userid is null check passed with 0 records
[2024-02-19T09:31:26.011+0000] {base.py:83} INFO - Using connection ID 'redshift' for task execution.
[2024-02-19T09:31:29.743+0000] {sql.py:432} INFO - Running statement: SELECT COUNT(*) FROM dim.dim_songs WHERE songid is null, parameters: None
[2024-02-19T09:31:31.724+0000] {taskinstance.py:2699} ERROR - Task failed with exception
Traceback (most recent call last):
  File "/home/airflow/.local/lib/python3.8/site-packages/airflow/models/taskinstance.py", line 433, in _execute_task
    result = execute_callable(context=context, **execute_callable_kwargs)
  File "/opt/airflow/plugins/final_project_operators/data_quality.py", line 30, in execute
    records = redshift.get_records(qa_check['check_sql'])
  File "/home/airflow/.local/lib/python3.8/site-packages/airflow/providers/common/sql/hooks/sql.py", line 255, in get_records
    return self.run(sql=sql, parameters=parameters, handler=fetch_all_handler)
  File "/home/airflow/.local/lib/python3.8/site-packages/airflow/providers/common/sql/hooks/sql.py", line 392, in run
    self._run_command(cur, sql_statement, parameters)
  File "/home/airflow/.local/lib/python3.8/site-packages/airflow/providers/common/sql/hooks/sql.py", line 437, in _run_command
    cur.execute(sql_statement)
psycopg2.errors.UndefinedColumn: column "songid" does not exist in dim_songs

[2024-02-19T09:31:31.747+0000] {taskinstance.py:1138} INFO - Marking task as UP_FOR_RETRY. dag_id=final_project, task_id=Run_data_quality_checks, execution_date=20240219T092505, start_date=20240219T093113, end_date=20240219T093131
[2024-02-19T09:31:31.756+0000] {standard_task_runner.py:107} ERROR - Failed to execute job 164 for task Run_data_quality_checks (column "songid" does not exist in dim_songs
; 765)
[2024-02-19T09:31:31.785+0000] {local_task_job_runner.py:234} INFO - Task exited with return code 1
[2024-02-19T09:31:31.794+0000] {taskinstance.py:3281} INFO - 0 downstream tasks scheduled from follow-on schedule check
