[2024-02-19T09:28:06.550+0000] {taskinstance.py:1957} INFO - Dependencies all met for dep_context=non-requeueable deps ti=<TaskInstance: final_project.Run_data_quality_checks manual__2024-02-19T09:25:05.177058+00:00 [queued]>
[2024-02-19T09:28:06.556+0000] {taskinstance.py:1957} INFO - Dependencies all met for dep_context=requeueable deps ti=<TaskInstance: final_project.Run_data_quality_checks manual__2024-02-19T09:25:05.177058+00:00 [queued]>
[2024-02-19T09:28:06.556+0000] {taskinstance.py:2171} INFO - Starting attempt 1 of 4
[2024-02-19T09:28:06.561+0000] {taskinstance.py:2192} INFO - Executing <Task(DataQualityOperator): Run_data_quality_checks> on 2024-02-19 09:25:05.177058+00:00
[2024-02-19T09:28:06.565+0000] {standard_task_runner.py:60} INFO - Started process 714 to run task
[2024-02-19T09:28:06.567+0000] {standard_task_runner.py:87} INFO - Running: ['***', 'tasks', 'run', 'final_project', 'Run_data_quality_checks', 'manual__2024-02-19T09:25:05.177058+00:00', '--job-id', '163', '--raw', '--subdir', 'DAGS_FOLDER/final_project.py', '--cfg-path', '/tmp/tmp6j23drix']
[2024-02-19T09:28:06.570+0000] {standard_task_runner.py:88} INFO - Job 163: Subtask Run_data_quality_checks
[2024-02-19T09:28:06.598+0000] {task_command.py:423} INFO - Running <TaskInstance: final_project.Run_data_quality_checks manual__2024-02-19T09:25:05.177058+00:00 [running]> on host b8bde2aaf906
[2024-02-19T09:28:06.639+0000] {taskinstance.py:2481} INFO - Exporting env vars: AIRFLOW_CTX_DAG_OWNER='udacity' AIRFLOW_CTX_DAG_ID='final_project' AIRFLOW_CTX_TASK_ID='Run_data_quality_checks' AIRFLOW_CTX_EXECUTION_DATE='2024-02-19T09:25:05.177058+00:00' AIRFLOW_CTX_TRY_NUMBER='1' AIRFLOW_CTX_DAG_RUN_ID='manual__2024-02-19T09:25:05.177058+00:00'
[2024-02-19T09:28:06.644+0000] {base.py:83} INFO - Using connection ID 'aws_credentials' for task execution.
[2024-02-19T09:28:06.645+0000] {connection_wrapper.py:378} INFO - AWS Connection (conn_id='aws_credentials', conn_type='aws') credentials retrieved from login and password.
[2024-02-19T09:28:06.655+0000] {base.py:83} INFO - Using connection ID 'redshift' for task execution.
[2024-02-19T09:28:11.606+0000] {sql.py:432} INFO - Running statement: SELECT COUNT(*) FROM users WHERE userid is null, parameters: None
[2024-02-19T09:28:12.662+0000] {taskinstance.py:2699} ERROR - Task failed with exception
Traceback (most recent call last):
  File "/home/airflow/.local/lib/python3.8/site-packages/airflow/models/taskinstance.py", line 433, in _execute_task
    result = execute_callable(context=context, **execute_callable_kwargs)
  File "/opt/airflow/plugins/final_project_operators/data_quality.py", line 30, in execute
    records = redshift.get_records(qa_check['check_sql'])
  File "/home/airflow/.local/lib/python3.8/site-packages/airflow/providers/common/sql/hooks/sql.py", line 255, in get_records
    return self.run(sql=sql, parameters=parameters, handler=fetch_all_handler)
  File "/home/airflow/.local/lib/python3.8/site-packages/airflow/providers/common/sql/hooks/sql.py", line 392, in run
    self._run_command(cur, sql_statement, parameters)
  File "/home/airflow/.local/lib/python3.8/site-packages/airflow/providers/common/sql/hooks/sql.py", line 437, in _run_command
    cur.execute(sql_statement)
psycopg2.errors.UndefinedTable: relation "users" does not exist

[2024-02-19T09:28:12.683+0000] {taskinstance.py:1138} INFO - Marking task as UP_FOR_RETRY. dag_id=final_project, task_id=Run_data_quality_checks, execution_date=20240219T092505, start_date=20240219T092806, end_date=20240219T092812
[2024-02-19T09:28:12.697+0000] {standard_task_runner.py:107} ERROR - Failed to execute job 163 for task Run_data_quality_checks (relation "users" does not exist
; 714)
[2024-02-19T09:28:12.751+0000] {local_task_job_runner.py:234} INFO - Task exited with return code 1
[2024-02-19T09:28:12.763+0000] {taskinstance.py:3281} INFO - 0 downstream tasks scheduled from follow-on schedule check
