[2024-02-18T08:58:56.809+0000] {taskinstance.py:1957} INFO - Dependencies all met for dep_context=non-requeueable deps ti=<TaskInstance: final_project.Load_user_dim_table manual__2024-02-18T08:55:13.724214+00:00 [queued]>
[2024-02-18T08:58:56.813+0000] {taskinstance.py:1957} INFO - Dependencies all met for dep_context=requeueable deps ti=<TaskInstance: final_project.Load_user_dim_table manual__2024-02-18T08:55:13.724214+00:00 [queued]>
[2024-02-18T08:58:56.814+0000] {taskinstance.py:2171} INFO - Starting attempt 1 of 1
[2024-02-18T08:58:56.820+0000] {taskinstance.py:2192} INFO - Executing <Task(LoadDimensionOperator): Load_user_dim_table> on 2024-02-18 08:55:13.724214+00:00
[2024-02-18T08:58:56.824+0000] {standard_task_runner.py:60} INFO - Started process 23359 to run task
[2024-02-18T08:58:56.826+0000] {standard_task_runner.py:87} INFO - Running: ['***', 'tasks', 'run', 'final_project', 'Load_user_dim_table', 'manual__2024-02-18T08:55:13.724214+00:00', '--job-id', '73', '--raw', '--subdir', 'DAGS_FOLDER/final_project.py', '--cfg-path', '/tmp/tmpkto48ikr']
[2024-02-18T08:58:56.828+0000] {standard_task_runner.py:88} INFO - Job 73: Subtask Load_user_dim_table
[2024-02-18T08:58:56.853+0000] {task_command.py:423} INFO - Running <TaskInstance: final_project.Load_user_dim_table manual__2024-02-18T08:55:13.724214+00:00 [running]> on host 6b28116ad14a
[2024-02-18T08:58:56.889+0000] {taskinstance.py:2481} INFO - Exporting env vars: AIRFLOW_CTX_DAG_OWNER='udacity' AIRFLOW_CTX_DAG_ID='final_project' AIRFLOW_CTX_TASK_ID='Load_user_dim_table' AIRFLOW_CTX_EXECUTION_DATE='2024-02-18T08:55:13.724214+00:00' AIRFLOW_CTX_TRY_NUMBER='1' AIRFLOW_CTX_DAG_RUN_ID='manual__2024-02-18T08:55:13.724214+00:00'
[2024-02-18T08:58:56.890+0000] {taskinstance.py:2699} ERROR - Task failed with exception
Traceback (most recent call last):
  File "/home/airflow/.local/lib/python3.8/site-packages/airflow/models/taskinstance.py", line 433, in _execute_task
    result = execute_callable(context=context, **execute_callable_kwargs)
  File "/opt/airflow/plugins/custom_operators/load_dimension.py", line 30, in execute
    aws_hook = AwsHook(self.aws_credentials_id)
NameError: name 'AwsHook' is not defined
[2024-02-18T08:58:56.895+0000] {taskinstance.py:1138} INFO - Marking task as FAILED. dag_id=final_project, task_id=Load_user_dim_table, execution_date=20240218T085513, start_date=20240218T085856, end_date=20240218T085856
[2024-02-18T08:58:56.899+0000] {standard_task_runner.py:107} ERROR - Failed to execute job 73 for task Load_user_dim_table (name 'AwsHook' is not defined; 23359)
[2024-02-18T08:58:56.920+0000] {local_task_job_runner.py:234} INFO - Task exited with return code 1
[2024-02-18T08:58:56.933+0000] {taskinstance.py:3281} INFO - 0 downstream tasks scheduled from follow-on schedule check
