[2024-02-13T15:02:34.702+0000] {taskinstance.py:1957} INFO - Dependencies all met for dep_context=non-requeueable deps ti=<TaskInstance: load_data_to_redshift.create_table manual__2024-02-13T15:02:33.632822+00:00 [queued]>
[2024-02-13T15:02:34.706+0000] {taskinstance.py:1957} INFO - Dependencies all met for dep_context=requeueable deps ti=<TaskInstance: load_data_to_redshift.create_table manual__2024-02-13T15:02:33.632822+00:00 [queued]>
[2024-02-13T15:02:34.706+0000] {taskinstance.py:2171} INFO - Starting attempt 1 of 1
[2024-02-13T15:02:34.713+0000] {taskinstance.py:2192} INFO - Executing <Task(PostgresOperator): create_table> on 2024-02-13 15:02:33.632822+00:00
[2024-02-13T15:02:34.716+0000] {standard_task_runner.py:60} INFO - Started process 6903 to run task
[2024-02-13T15:02:34.719+0000] {standard_task_runner.py:87} INFO - Running: ['***', 'tasks', 'run', 'load_data_to_redshift', 'create_table', 'manual__2024-02-13T15:02:33.632822+00:00', '--job-id', '8', '--raw', '--subdir', 'DAGS_FOLDER/l3_e4_s3_to_redshift.py', '--cfg-path', '/tmp/tmpl379wd0o']
[2024-02-13T15:02:34.722+0000] {standard_task_runner.py:88} INFO - Job 8: Subtask create_table
[2024-02-13T15:02:34.753+0000] {task_command.py:423} INFO - Running <TaskInstance: load_data_to_redshift.create_table manual__2024-02-13T15:02:33.632822+00:00 [running]> on host 53c8d9721d47
[2024-02-13T15:02:34.795+0000] {taskinstance.py:2481} INFO - Exporting env vars: AIRFLOW_CTX_DAG_OWNER='***' AIRFLOW_CTX_DAG_ID='load_data_to_redshift' AIRFLOW_CTX_TASK_ID='create_table' AIRFLOW_CTX_EXECUTION_DATE='2024-02-13T15:02:33.632822+00:00' AIRFLOW_CTX_TRY_NUMBER='1' AIRFLOW_CTX_DAG_RUN_ID='manual__2024-02-13T15:02:33.632822+00:00'
[2024-02-13T15:02:34.796+0000] {sql.py:276} INFO - Executing: 
CREATE TABLE IF NOT EXISTS trips (
trip_id INTEGER NOT NULL,
start_time TIMESTAMP NOT NULL,
end_time TIMESTAMP NOT NULL,
bikeid INTEGER NOT NULL,
tripduration DECIMAL(16,2) NOT NULL,
from_station_id INTEGER NOT NULL,
from_station_name VARCHAR(100) NOT NULL,
to_station_id INTEGER NOT NULL,
to_station_name VARCHAR(100) NOT NULL,
usertype VARCHAR(20),
gender VARCHAR(6),
birthyear INTEGER,
PRIMARY KEY(trip_id))
DISTSTYLE ALL;
[2024-02-13T15:02:34.801+0000] {base.py:83} INFO - Using connection ID 'redshift' for task execution.
[2024-02-13T15:02:34.872+0000] {base.py:83} INFO - Using connection ID 'redshift' for task execution.
[2024-02-13T15:03:50.022+0000] {taskinstance.py:2699} ERROR - Task failed with exception
Traceback (most recent call last):
  File "/home/airflow/.local/lib/python3.8/site-packages/redshift_connector/core.py", line 626, in __init__
    self._usock.connect(hostport)
ConnectionRefusedError: [Errno 111] Connection refused

During handling of the above exception, another exception occurred:

Traceback (most recent call last):
  File "/home/airflow/.local/lib/python3.8/site-packages/airflow/models/taskinstance.py", line 433, in _execute_task
    result = execute_callable(context=context, **execute_callable_kwargs)
  File "/home/airflow/.local/lib/python3.8/site-packages/airflow/providers/common/sql/operators/sql.py", line 282, in execute
    output = hook.run(
  File "/home/airflow/.local/lib/python3.8/site-packages/airflow/providers/common/sql/hooks/sql.py", line 385, in run
    with closing(self.get_conn()) as conn:
  File "/home/airflow/.local/lib/python3.8/site-packages/airflow/providers/amazon/aws/hooks/redshift_sql.py", line 199, in get_conn
    return redshift_connector.connect(**conn_kwargs)
  File "/home/airflow/.local/lib/python3.8/site-packages/redshift_connector/__init__.py", line 376, in connect
    return Connection(
  File "/home/airflow/.local/lib/python3.8/site-packages/redshift_connector/core.py", line 689, in __init__
    raise InterfaceError("communication error", e)
redshift_connector.error.InterfaceError: ('communication error', ConnectionRefusedError(111, 'Connection refused'))
[2024-02-13T15:03:50.028+0000] {taskinstance.py:1138} INFO - Marking task as FAILED. dag_id=load_data_to_redshift, task_id=create_table, execution_date=20240213T150233, start_date=20240213T150234, end_date=20240213T150350
[2024-02-13T15:03:50.038+0000] {standard_task_runner.py:107} ERROR - Failed to execute job 8 for task create_table (('communication error', ConnectionRefusedError(111, 'Connection refused')); 6903)
[2024-02-13T15:03:50.060+0000] {local_task_job_runner.py:234} INFO - Task exited with return code 1
[2024-02-13T15:03:50.073+0000] {taskinstance.py:3281} INFO - 0 downstream tasks scheduled from follow-on schedule check
