[2024-02-13T14:43:38.053+0000] {taskinstance.py:1957} INFO - Dependencies all met for dep_context=non-requeueable deps ti=<TaskInstance: load_data_to_redshift.create_table manual__2024-02-13T14:43:37.078304+00:00 [queued]>
[2024-02-13T14:43:38.057+0000] {taskinstance.py:1957} INFO - Dependencies all met for dep_context=requeueable deps ti=<TaskInstance: load_data_to_redshift.create_table manual__2024-02-13T14:43:37.078304+00:00 [queued]>
[2024-02-13T14:43:38.057+0000] {taskinstance.py:2171} INFO - Starting attempt 1 of 1
[2024-02-13T14:43:38.064+0000] {taskinstance.py:2192} INFO - Executing <Task(PostgresOperator): create_table> on 2024-02-13 14:43:37.078304+00:00
[2024-02-13T14:43:38.067+0000] {standard_task_runner.py:60} INFO - Started process 6604 to run task
[2024-02-13T14:43:38.070+0000] {standard_task_runner.py:87} INFO - Running: ['***', 'tasks', 'run', 'load_data_to_redshift', 'create_table', 'manual__2024-02-13T14:43:37.078304+00:00', '--job-id', '4', '--raw', '--subdir', 'DAGS_FOLDER/l3_e4_s3_to_redshift.py', '--cfg-path', '/tmp/tmprwbu1cfg']
[2024-02-13T14:43:38.072+0000] {standard_task_runner.py:88} INFO - Job 4: Subtask create_table
[2024-02-13T14:43:38.099+0000] {task_command.py:423} INFO - Running <TaskInstance: load_data_to_redshift.create_table manual__2024-02-13T14:43:37.078304+00:00 [running]> on host 53c8d9721d47
[2024-02-13T14:43:38.137+0000] {taskinstance.py:2481} INFO - Exporting env vars: AIRFLOW_CTX_DAG_OWNER='***' AIRFLOW_CTX_DAG_ID='load_data_to_redshift' AIRFLOW_CTX_TASK_ID='create_table' AIRFLOW_CTX_EXECUTION_DATE='2024-02-13T14:43:37.078304+00:00' AIRFLOW_CTX_TRY_NUMBER='1' AIRFLOW_CTX_DAG_RUN_ID='manual__2024-02-13T14:43:37.078304+00:00'
[2024-02-13T14:43:38.138+0000] {sql.py:276} INFO - Executing: 
CREATE TABLE IF NOT EXISTS trips (
trip_id INTEGER NOT NULL,
start_time TIMESTAMP NOT NULL,
end_time TIMESTAMP NOT NULL,
bikeid INTEGER NOT NULL,
tripduration DECIMAL(16,2) NOT NULL,
from_station_id INTEGER NOT NULL,
from_station_name VARCHAR(100) NOT NULL,
to_station_id INTEGER NOT NULL,
to_station_name VARCHAR(100) NOT NULL,
usertype VARCHAR(20),
gender VARCHAR(6),
birthyear INTEGER,
PRIMARY KEY(trip_id))
DISTSTYLE ALL;
[2024-02-13T14:43:38.143+0000] {base.py:83} INFO - Using connection ID 'redshift' for task execution.
[2024-02-13T14:43:38.209+0000] {base.py:83} INFO - Using connection ID 'redshift' for task execution.
[2024-02-13T14:44:53.359+0000] {taskinstance.py:2699} ERROR - Task failed with exception
Traceback (most recent call last):
  File "/home/airflow/.local/lib/python3.8/site-packages/redshift_connector/core.py", line 626, in __init__
    self._usock.connect(hostport)
ConnectionRefusedError: [Errno 111] Connection refused

During handling of the above exception, another exception occurred:

Traceback (most recent call last):
  File "/home/airflow/.local/lib/python3.8/site-packages/airflow/models/taskinstance.py", line 433, in _execute_task
    result = execute_callable(context=context, **execute_callable_kwargs)
  File "/home/airflow/.local/lib/python3.8/site-packages/airflow/providers/common/sql/operators/sql.py", line 282, in execute
    output = hook.run(
  File "/home/airflow/.local/lib/python3.8/site-packages/airflow/providers/common/sql/hooks/sql.py", line 385, in run
    with closing(self.get_conn()) as conn:
  File "/home/airflow/.local/lib/python3.8/site-packages/airflow/providers/amazon/aws/hooks/redshift_sql.py", line 199, in get_conn
    return redshift_connector.connect(**conn_kwargs)
  File "/home/airflow/.local/lib/python3.8/site-packages/redshift_connector/__init__.py", line 376, in connect
    return Connection(
  File "/home/airflow/.local/lib/python3.8/site-packages/redshift_connector/core.py", line 689, in __init__
    raise InterfaceError("communication error", e)
redshift_connector.error.InterfaceError: ('communication error', ConnectionRefusedError(111, 'Connection refused'))
[2024-02-13T14:44:53.364+0000] {taskinstance.py:1138} INFO - Marking task as FAILED. dag_id=load_data_to_redshift, task_id=create_table, execution_date=20240213T144337, start_date=20240213T144338, end_date=20240213T144453
[2024-02-13T14:44:53.371+0000] {standard_task_runner.py:107} ERROR - Failed to execute job 4 for task create_table (('communication error', ConnectionRefusedError(111, 'Connection refused')); 6604)
[2024-02-13T14:44:53.411+0000] {local_task_job_runner.py:234} INFO - Task exited with return code 1
[2024-02-13T14:44:53.426+0000] {taskinstance.py:3281} INFO - 0 downstream tasks scheduled from follow-on schedule check
