[2024-02-18T09:44:41.921+0000] {taskinstance.py:1957} INFO - Dependencies all met for dep_context=non-requeueable deps ti=<TaskInstance: final_project.Run_data_quality_checks manual__2024-02-18T09:35:04.108286+00:00 [queued]>
[2024-02-18T09:44:41.927+0000] {taskinstance.py:1957} INFO - Dependencies all met for dep_context=requeueable deps ti=<TaskInstance: final_project.Run_data_quality_checks manual__2024-02-18T09:35:04.108286+00:00 [queued]>
[2024-02-18T09:44:41.928+0000] {taskinstance.py:2171} INFO - Starting attempt 1 of 4
[2024-02-18T09:44:41.934+0000] {taskinstance.py:2192} INFO - Executing <Task(DataQualityOperator): Run_data_quality_checks> on 2024-02-18 09:35:04.108286+00:00
[2024-02-18T09:44:41.938+0000] {standard_task_runner.py:60} INFO - Started process 24127 to run task
[2024-02-18T09:44:41.940+0000] {standard_task_runner.py:87} INFO - Running: ['***', 'tasks', 'run', 'final_project', 'Run_data_quality_checks', 'manual__2024-02-18T09:35:04.108286+00:00', '--job-id', '95', '--raw', '--subdir', 'DAGS_FOLDER/final_project.py', '--cfg-path', '/tmp/tmpznovsgmk']
[2024-02-18T09:44:41.942+0000] {standard_task_runner.py:88} INFO - Job 95: Subtask Run_data_quality_checks
[2024-02-18T09:44:41.967+0000] {task_command.py:423} INFO - Running <TaskInstance: final_project.Run_data_quality_checks manual__2024-02-18T09:35:04.108286+00:00 [running]> on host 6b28116ad14a
[2024-02-18T09:44:42.003+0000] {taskinstance.py:2481} INFO - Exporting env vars: AIRFLOW_CTX_DAG_OWNER='udacity' AIRFLOW_CTX_DAG_ID='final_project' AIRFLOW_CTX_TASK_ID='Run_data_quality_checks' AIRFLOW_CTX_EXECUTION_DATE='2024-02-18T09:35:04.108286+00:00' AIRFLOW_CTX_TRY_NUMBER='1' AIRFLOW_CTX_DAG_RUN_ID='manual__2024-02-18T09:35:04.108286+00:00'
[2024-02-18T09:44:42.009+0000] {base.py:83} INFO - Using connection ID 'aws_credentials' for task execution.
[2024-02-18T09:44:42.010+0000] {connection_wrapper.py:378} INFO - AWS Connection (conn_id='aws_credentials', conn_type='aws') credentials retrieved from login and password.
[2024-02-18T09:44:42.020+0000] {base.py:83} INFO - Using connection ID 'redshift' for task execution.
[2024-02-18T09:44:47.798+0000] {sql.py:432} INFO - Running statement: select count(*) from staging.staging_events, parameters: None
[2024-02-18T09:44:49.070+0000] {sql.py:441} INFO - Rows affected: 1
[2024-02-18T09:44:49.745+0000] {taskinstance.py:2699} ERROR - Task failed with exception
Traceback (most recent call last):
  File "/home/airflow/.local/lib/python3.8/site-packages/airflow/models/taskinstance.py", line 433, in _execute_task
    result = execute_callable(context=context, **execute_callable_kwargs)
  File "/opt/airflow/plugins/custom_operators/data_quality.py", line 36, in execute
    logging.info(f"Data quality on table {table} check passed with {records[0][0]} records")
NameError: name 'logging' is not defined
[2024-02-18T09:44:49.758+0000] {taskinstance.py:1138} INFO - Marking task as UP_FOR_RETRY. dag_id=final_project, task_id=Run_data_quality_checks, execution_date=20240218T093504, start_date=20240218T094441, end_date=20240218T094449
[2024-02-18T09:44:49.768+0000] {standard_task_runner.py:107} ERROR - Failed to execute job 95 for task Run_data_quality_checks (name 'logging' is not defined; 24127)
[2024-02-18T09:44:49.788+0000] {local_task_job_runner.py:234} INFO - Task exited with return code 1
[2024-02-18T09:44:49.799+0000] {taskinstance.py:3281} INFO - 0 downstream tasks scheduled from follow-on schedule check
