[2024-02-18T09:54:11.462+0000] {taskinstance.py:1957} INFO - Dependencies all met for dep_context=non-requeueable deps ti=<TaskInstance: final_project.Run_data_quality_checks manual__2024-02-18T09:35:04.108286+00:00 [queued]>
[2024-02-18T09:54:11.469+0000] {taskinstance.py:1957} INFO - Dependencies all met for dep_context=requeueable deps ti=<TaskInstance: final_project.Run_data_quality_checks manual__2024-02-18T09:35:04.108286+00:00 [queued]>
[2024-02-18T09:54:11.469+0000] {taskinstance.py:2171} INFO - Starting attempt 4 of 4
[2024-02-18T09:54:11.478+0000] {taskinstance.py:2192} INFO - Executing <Task(DataQualityOperator): Run_data_quality_checks> on 2024-02-18 09:35:04.108286+00:00
[2024-02-18T09:54:11.486+0000] {standard_task_runner.py:60} INFO - Started process 24280 to run task
[2024-02-18T09:54:11.488+0000] {standard_task_runner.py:87} INFO - Running: ['***', 'tasks', 'run', 'final_project', 'Run_data_quality_checks', 'manual__2024-02-18T09:35:04.108286+00:00', '--job-id', '98', '--raw', '--subdir', 'DAGS_FOLDER/final_project.py', '--cfg-path', '/tmp/tmpyneh8zb_']
[2024-02-18T09:54:11.491+0000] {standard_task_runner.py:88} INFO - Job 98: Subtask Run_data_quality_checks
[2024-02-18T09:54:11.533+0000] {task_command.py:423} INFO - Running <TaskInstance: final_project.Run_data_quality_checks manual__2024-02-18T09:35:04.108286+00:00 [running]> on host 6b28116ad14a
[2024-02-18T09:54:11.576+0000] {taskinstance.py:2481} INFO - Exporting env vars: AIRFLOW_CTX_DAG_OWNER='udacity' AIRFLOW_CTX_DAG_ID='final_project' AIRFLOW_CTX_TASK_ID='Run_data_quality_checks' AIRFLOW_CTX_EXECUTION_DATE='2024-02-18T09:35:04.108286+00:00' AIRFLOW_CTX_TRY_NUMBER='4' AIRFLOW_CTX_DAG_RUN_ID='manual__2024-02-18T09:35:04.108286+00:00'
[2024-02-18T09:54:11.582+0000] {base.py:83} INFO - Using connection ID 'aws_credentials' for task execution.
[2024-02-18T09:54:11.583+0000] {connection_wrapper.py:378} INFO - AWS Connection (conn_id='aws_credentials', conn_type='aws') credentials retrieved from login and password.
[2024-02-18T09:54:11.593+0000] {base.py:83} INFO - Using connection ID 'redshift' for task execution.
[2024-02-18T09:54:17.308+0000] {sql.py:432} INFO - Running statement: select count(*) from staging.staging_events, parameters: None
[2024-02-18T09:54:18.842+0000] {sql.py:441} INFO - Rows affected: 1
[2024-02-18T09:54:19.668+0000] {taskinstance.py:2699} ERROR - Task failed with exception
Traceback (most recent call last):
  File "/home/airflow/.local/lib/python3.8/site-packages/airflow/models/taskinstance.py", line 433, in _execute_task
    result = execute_callable(context=context, **execute_callable_kwargs)
  File "/opt/airflow/plugins/custom_operators/data_quality.py", line 36, in execute
    logging.info(f"Data quality on table {table} check passed with {records[0][0]} records")
NameError: name 'logging' is not defined
[2024-02-18T09:54:19.700+0000] {taskinstance.py:1138} INFO - Marking task as FAILED. dag_id=final_project, task_id=Run_data_quality_checks, execution_date=20240218T093504, start_date=20240218T095411, end_date=20240218T095419
[2024-02-18T09:54:19.714+0000] {standard_task_runner.py:107} ERROR - Failed to execute job 98 for task Run_data_quality_checks (name 'logging' is not defined; 24280)
[2024-02-18T09:54:19.761+0000] {local_task_job_runner.py:234} INFO - Task exited with return code 1
[2024-02-18T09:54:19.773+0000] {taskinstance.py:3281} INFO - 0 downstream tasks scheduled from follow-on schedule check
